[2025-02-05T12:15:26.398+0000] {local_task_job_runner.py:123} INFO - ::group::Pre task execution logs
[2025-02-05T12:15:26.430+0000] {taskinstance.py:2613} INFO - Dependencies all met for dep_context=non-requeueable deps ti=<TaskInstance: extract_to_local.extract_postgres scheduled__2025-02-04T00:00:00+00:00 [queued]>
[2025-02-05T12:15:26.443+0000] {taskinstance.py:2613} INFO - Dependencies all met for dep_context=requeueable deps ti=<TaskInstance: extract_to_local.extract_postgres scheduled__2025-02-04T00:00:00+00:00 [queued]>
[2025-02-05T12:15:26.444+0000] {taskinstance.py:2866} INFO - Starting attempt 2 of 2
[2025-02-05T12:15:26.465+0000] {taskinstance.py:2889} INFO - Executing <Task(BashOperator): extract_postgres> on 2025-02-04 00:00:00+00:00
[2025-02-05T12:15:26.473+0000] {warnings.py:112} WARNING - /home/***/.local/lib/python3.12/site-packages/***/task/task_runner/standard_task_runner.py:70: DeprecationWarning: This process (pid=219) is multi-threaded, use of fork() may lead to deadlocks in the child.
  pid = os.fork()

[2025-02-05T12:15:26.476+0000] {standard_task_runner.py:72} INFO - Started process 220 to run task
[2025-02-05T12:15:26.477+0000] {standard_task_runner.py:104} INFO - Running: ['***', 'tasks', 'run', 'extract_to_local', 'extract_postgres', 'scheduled__2025-02-04T00:00:00+00:00', '--job-id', '8', '--raw', '--subdir', 'DAGS_FOLDER/extract_local.py', '--cfg-path', '/tmp/tmpheg498wg']
[2025-02-05T12:15:26.479+0000] {standard_task_runner.py:105} INFO - Job 8: Subtask extract_postgres
[2025-02-05T12:15:26.557+0000] {task_command.py:467} INFO - Running <TaskInstance: extract_to_local.extract_postgres scheduled__2025-02-04T00:00:00+00:00 [running]> on host 810dad3d0bb9
[2025-02-05T12:15:26.698+0000] {taskinstance.py:3132} INFO - Exporting env vars: AIRFLOW_CTX_DAG_OWNER='***' AIRFLOW_CTX_DAG_ID='extract_to_local' AIRFLOW_CTX_TASK_ID='extract_postgres' AIRFLOW_CTX_EXECUTION_DATE='2025-02-04T00:00:00+00:00' AIRFLOW_CTX_TRY_NUMBER='2' AIRFLOW_CTX_DAG_RUN_ID='scheduled__2025-02-04T00:00:00+00:00'
[2025-02-05T12:15:26.700+0000] {taskinstance.py:731} INFO - ::endgroup::
[2025-02-05T12:15:26.736+0000] {subprocess.py:78} INFO - Tmp dir root location: /tmp
[2025-02-05T12:15:26.737+0000] {subprocess.py:88} INFO - Running command: ['/usr/bin/bash', '-c', 'docker-compose run --rm meltano run tap-postgres target-parquet']
[2025-02-05T12:15:26.753+0000] {subprocess.py:99} INFO - Output:
[2025-02-05T12:15:26.756+0000] {subprocess.py:106} INFO - /usr/bin/bash: line 1: docker-compose: command not found
[2025-02-05T12:15:26.756+0000] {subprocess.py:110} INFO - Command exited with return code 127
[2025-02-05T12:15:26.775+0000] {taskinstance.py:3311} ERROR - Task failed with exception
Traceback (most recent call last):
  File "/home/airflow/.local/lib/python3.12/site-packages/airflow/models/taskinstance.py", line 767, in _execute_task
    result = _execute_callable(context=context, **execute_callable_kwargs)
             ^^^^^^^^^^^^^^^^^^^^^^^^^^^^^^^^^^^^^^^^^^^^^^^^^^^^^^^^^^^^^
  File "/home/airflow/.local/lib/python3.12/site-packages/airflow/models/taskinstance.py", line 733, in _execute_callable
    return ExecutionCallableRunner(
           ^^^^^^^^^^^^^^^^^^^^^^^^
  File "/home/airflow/.local/lib/python3.12/site-packages/airflow/utils/operator_helpers.py", line 252, in run
    return self.func(*args, **kwargs)
           ^^^^^^^^^^^^^^^^^^^^^^^^^^
  File "/home/airflow/.local/lib/python3.12/site-packages/airflow/models/baseoperator.py", line 422, in wrapper
    return func(self, *args, **kwargs)
           ^^^^^^^^^^^^^^^^^^^^^^^^^^^
  File "/home/airflow/.local/lib/python3.12/site-packages/airflow/operators/bash.py", line 276, in execute
    raise AirflowException(
airflow.exceptions.AirflowException: Bash command failed. The command returned a non-zero exit code 127.
[2025-02-05T12:15:26.785+0000] {taskinstance.py:1225} INFO - Marking task as FAILED. dag_id=extract_to_local, task_id=extract_postgres, run_id=scheduled__2025-02-04T00:00:00+00:00, execution_date=20250204T000000, start_date=20250205T121526, end_date=20250205T121526
[2025-02-05T12:15:26.806+0000] {taskinstance.py:340} INFO - ::group::Post task execution logs
[2025-02-05T12:15:26.807+0000] {standard_task_runner.py:124} ERROR - Failed to execute job 8 for task extract_postgres (Bash command failed. The command returned a non-zero exit code 127.; 220)
Traceback (most recent call last):
  File "/home/airflow/.local/lib/python3.12/site-packages/airflow/task/task_runner/standard_task_runner.py", line 117, in _start_by_fork
    ret = args.func(args, dag=self.dag)
          ^^^^^^^^^^^^^^^^^^^^^^^^^^^^^
  File "/home/airflow/.local/lib/python3.12/site-packages/airflow/cli/cli_config.py", line 49, in command
    return func(*args, **kwargs)
           ^^^^^^^^^^^^^^^^^^^^^
  File "/home/airflow/.local/lib/python3.12/site-packages/airflow/utils/cli.py", line 116, in wrapper
    return f(*args, **kwargs)
           ^^^^^^^^^^^^^^^^^^
  File "/home/airflow/.local/lib/python3.12/site-packages/airflow/cli/commands/task_command.py", line 483, in task_run
    task_return_code = _run_task_by_selected_method(args, _dag, ti)
                       ^^^^^^^^^^^^^^^^^^^^^^^^^^^^^^^^^^^^^^^^^^^^
  File "/home/airflow/.local/lib/python3.12/site-packages/airflow/cli/commands/task_command.py", line 256, in _run_task_by_selected_method
    return _run_raw_task(args, ti)
           ^^^^^^^^^^^^^^^^^^^^^^^
  File "/home/airflow/.local/lib/python3.12/site-packages/airflow/cli/commands/task_command.py", line 341, in _run_raw_task
    return ti._run_raw_task(
           ^^^^^^^^^^^^^^^^^
  File "/home/airflow/.local/lib/python3.12/site-packages/airflow/utils/session.py", line 97, in wrapper
    return func(*args, session=session, **kwargs)
           ^^^^^^^^^^^^^^^^^^^^^^^^^^^^^^^^^^^^^^
  File "/home/airflow/.local/lib/python3.12/site-packages/airflow/models/taskinstance.py", line 3005, in _run_raw_task
    return _run_raw_task(
           ^^^^^^^^^^^^^^
  File "/home/airflow/.local/lib/python3.12/site-packages/airflow/models/taskinstance.py", line 273, in _run_raw_task
    TaskInstance._execute_task_with_callbacks(
  File "/home/airflow/.local/lib/python3.12/site-packages/airflow/models/taskinstance.py", line 3159, in _execute_task_with_callbacks
    result = self._execute_task(context, task_orig)
             ^^^^^^^^^^^^^^^^^^^^^^^^^^^^^^^^^^^^^^
  File "/home/airflow/.local/lib/python3.12/site-packages/airflow/models/taskinstance.py", line 3183, in _execute_task
    return _execute_task(self, context, task_orig)
           ^^^^^^^^^^^^^^^^^^^^^^^^^^^^^^^^^^^^^^^
  File "/home/airflow/.local/lib/python3.12/site-packages/airflow/models/taskinstance.py", line 767, in _execute_task
    result = _execute_callable(context=context, **execute_callable_kwargs)
             ^^^^^^^^^^^^^^^^^^^^^^^^^^^^^^^^^^^^^^^^^^^^^^^^^^^^^^^^^^^^^
  File "/home/airflow/.local/lib/python3.12/site-packages/airflow/models/taskinstance.py", line 733, in _execute_callable
    return ExecutionCallableRunner(
           ^^^^^^^^^^^^^^^^^^^^^^^^
  File "/home/airflow/.local/lib/python3.12/site-packages/airflow/utils/operator_helpers.py", line 252, in run
    return self.func(*args, **kwargs)
           ^^^^^^^^^^^^^^^^^^^^^^^^^^
  File "/home/airflow/.local/lib/python3.12/site-packages/airflow/models/baseoperator.py", line 422, in wrapper
    return func(self, *args, **kwargs)
           ^^^^^^^^^^^^^^^^^^^^^^^^^^^
  File "/home/airflow/.local/lib/python3.12/site-packages/airflow/operators/bash.py", line 276, in execute
    raise AirflowException(
airflow.exceptions.AirflowException: Bash command failed. The command returned a non-zero exit code 127.
[2025-02-05T12:15:26.860+0000] {local_task_job_runner.py:266} INFO - Task exited with return code 1
[2025-02-05T12:15:26.893+0000] {taskinstance.py:3895} INFO - 0 downstream tasks scheduled from follow-on schedule check
[2025-02-05T12:15:26.894+0000] {local_task_job_runner.py:245} INFO - ::endgroup::
